Workbook

Sheet 표지
H4: [자화전자][SI][설비IF]광학CM_VTask_설비온라인
B8: 현장 통합 테스트 - 설비명
B11: ="문서번호 : " & REPLACE(LEFT(CELL("filename",A1),FIND(".xls",CELL("filename",A1))-1),1,FIND("[",CELL("filename",A1)),"") -> 문서번호 : 자화전자템플릿_광학CM_VTask_설비온라인_사전점검 및 현장통합Test_결과서(XML)_v0.1
S16: 관리부서 : 공정제어팀
C19: 소속 | E19: LG CNS | H19: 작성자 | J19: 배준석 책임
C20: 소속 | E20: LG CNS | H20: 검토자 | J20: 배준석 책임
C21: 소속 | E21: LG CNS | H21: 승인자 | J21: 박민용 선임
C22: 소속 | E22: LG 이노텍 | H22: 검수자 | J22: 오현학 책임
G24: Copyright ⓒ LG CNS LG CNS의 사전 승인 없이 본 내용의 전부 또는 일부에 대한 복사, 배포, 사용을 금합니다.

Sheet 개정이력
E3: 개 정 이 력
B5: Ver. | C5: 변경일 | D5: 관련 근거 | E5: 변경 내용 | F5: 작성자 | G5: 승인자
B6: 1.0 | C6: 46168 | D6: - | E6: 최초 작성 | F6: 배준석 | G6: 박민용
D7: -

Sheet Test 결과 종합
A1: ▣ 테스트 결과
B3: 테스트 일자 : | C3: 44868
B5: 구분 | C5: 설비명 | D5: 금일 테스트 결과 | H5: 테스트 결과 누적 | P5: 비고
D6: 금일 테스트케이스 | E6: OK | F6: NG | G6: SKIP | H6: 전체 테스트케이스 | I6: 테스트 진척률 | J6: OK | L6: NG | N6: SKIP
J7: 개수 | K7: 비율 | L7: 개수 | M7: 비율 | N7: 개수 | O7: 비율
B8: 메시지 테스트 | C8: Unit#1 | D8: =COUNTIFS('01) 메세지 테스트'!$L$5:$L$133,'Test 결과 종합'!$C$3) -> 0 | E8: =COUNTIFS('01) 메세지 테스트'!$L$5:$L$133,'Test 결과 종합'!$C$3,'01) 메세지 테스트'!$M$5:$M$133,'Test 결과 종합'!E$6) -> 0 | F8: =COUNTIFS('01) 메세지 테스트'!$L$5:$L$133,'Test 결과 종합'!$C$3,'01) 메세지 테스트'!$M$5:$M$133,'Test 결과 종합'!F$6) -> 0 | G8: =COUNTIFS('01) 메세지 테스트'!$L$5:$L$133,'Test 결과 종합'!$C$3,'01) 메세지 테스트'!$M$5:$M$133,'Test 결과 종합'!G$6) -> 0 | H8: =MAX('01) 메세지 테스트'!$B$5:$B$133)-COUNTIF('01) 메세지 테스트'!M5:M133,"N/A") -> 34 | I8: =K8 -> 0 | J8: =COUNTIFS('01) 메세지 테스트'!$M$5:$M$133,'Test 결과 종합'!J$6) -> 0 | K8: =IF(J8=0,0,J8/H8) -> 0 | L8: =COUNTIFS('01) 메세지 테스트'!$M$5:$M$133,'Test 결과 종합'!L$6) -> 0 | M8: =IF(L8=0,0,L8/H8) -> 0 | N8: =COUNTIFS('01) 메세지 테스트'!$M$5:$M$133,'Test 결과 종합'!N$6) -> 0 | O8: =IF(N8=0,0,N8/H8) -> 0
C9: Unit#2 | D9: =COUNTIFS('01) 메세지 테스트'!$P$5:$P$133,'Test 결과 종합'!$C$3) -> 0 | E9: =COUNTIFS('01) 메세지 테스트'!$P$5:$P$133,'Test 결과 종합'!$C$3,'01) 메세지 테스트'!$Q$5:$Q$133,'Test 결과 종합'!E$6) -> 0 | F9: =COUNTIFS('01) 메세지 테스트'!$P$5:$P$133,'Test 결과 종합'!$C$3,'01) 메세지 테스트'!$Q$5:$Q$133,'Test 결과 종합'!F$6) -> 0 | G9: =COUNTIFS('01) 메세지 테스트'!$P$5:$P$133,'Test 결과 종합'!$C$3,'01) 메세지 테스트'!$Q$5:$Q$133,'Test 결과 종합'!G$6) -> 0 | H9: =MAX('01) 메세지 테스트'!$B$5:$B$133)-COUNTIF('01) 메세지 테스트'!Q5:Q133,"N/A") -> 34 | I9: =K9 -> 0 | J9: =COUNTIFS('01) 메세지 테스트'!$Q$5:$Q$133,'Test 결과 종합'!J$6) -> 0 | K9: =IF(J9=0,0,J9/H9) -> 0 | L9: =COUNTIFS('01) 메세지 테스트'!$Q$5:$Q$133,'Test 결과 종합'!L$6) -> 0 | M9: =IF(L9=0,0,L9/H9) -> 0 | N9: =COUNTIFS('01) 메세지 테스트'!$Q$5:$Q$133,'Test 결과 종합'!N$6) -> 0 | O9: =IF(N9=0,0,N9/H9) -> 0
C10: Unit#3 | D10: =COUNTIFS('01) 메세지 테스트'!$T$5:$T$133,'Test 결과 종합'!$C$3) -> 0 | E10: =COUNTIFS('01) 메세지 테스트'!$T$5:$T$133,'Test 결과 종합'!$C$3,'01) 메세지 테스트'!$U$5:$U$133,'Test 결과 종합'!E$6) -> 0 | F10: =COUNTIFS('01) 메세지 테스트'!$T$5:$T$133,'Test 결과 종합'!$C$3,'01) 메세지 테스트'!$U$5:$U$133,'Test 결과 종합'!F$6) -> 0 | G10: =COUNTIFS('01) 메세지 테스트'!$T$5:$T$133,'Test 결과 종합'!$C$3,'01) 메세지 테스트'!$U$5:$U$133,'Test 결과 종합'!G$6) -> 0 | H10: =MAX('01) 메세지 테스트'!$B$5:$B$133)-COUNTIF('01) 메세지 테스트'!U5:U133,"N/A") -> 34 | I10: =K10 -> 0 | J10: =COUNTIFS('01) 메세지 테스트'!$U$5:$U$133,'Test 결과 종합'!J$6) -> 0 | K10: =IF(J10=0,0,J10/H10) -> 0 | L10: =COUNTIFS('01) 메세지 테스트'!$U$5:$U$133,'Test 결과 종합'!L$6) -> 0 | M10: =IF(L10=0,0,L10/H10) -> 0 | N10: =COUNTIFS('01) 메세지 테스트'!$U$5:$U$133,'Test 결과 종합'!N$6) -> 0 | O10: =IF(N10=0,0,N10/H10) -> 0
C11: Unit#4 | D11: =COUNTIFS('01) 메세지 테스트'!$X$5:$X$133,'Test 결과 종합'!$C$3) -> 0 | E11: =COUNTIFS('01) 메세지 테스트'!$X$5:$X$133,'Test 결과 종합'!$C$3,'01) 메세지 테스트'!$Y$5:$Y$133,'Test 결과 종합'!E$6) -> 0 | F11: =COUNTIFS('01) 메세지 테스트'!$X$5:$X$133,'Test 결과 종합'!$C$3,'01) 메세지 테스트'!$Y$5:$Y$133,'Test 결과 종합'!F$6) -> 0 | G11: =COUNTIFS('01) 메세지 테스트'!$X$5:$X$133,'Test 결과 종합'!$C$3,'01) 메세지 테스트'!$Y$5:$Y$133,'Test 결과 종합'!G$6) -> 0 | H11: =MAX('01) 메세지 테스트'!$B$5:$B$133)-COUNTIF('01) 메세지 테스트'!Y5:Y133,"N/A") -> 34 | I11: =K11 -> 0 | J11: =COUNTIFS('01) 메세지 테스트'!$Y$5:$Y$133,'Test 결과 종합'!J$6) -> 0 | K11: =IF(J11=0,0,J11/H11) -> 0 | L11: =COUNTIFS('01) 메세지 테스트'!$Y$5:$Y$133,'Test 결과 종합'!L$6) -> 0 | M11: =IF(L11=0,0,L11/H11) -> 0 | N11: =COUNTIFS('01) 메세지 테스트'!$Y$5:$Y$133,'Test 결과 종합'!N$6) -> 0 | O11: =IF(N11=0,0,N11/H11) -> 0
C12: Unit#5 | D12: =COUNTIFS('01) 메세지 테스트'!$AB$5:$AB$133,'Test 결과 종합'!$C$3) -> 0 | E12: =COUNTIFS('01) 메세지 테스트'!$AB$5:$AB$133,'Test 결과 종합'!$C$3,'01) 메세지 테스트'!$AC$5:$AC$133,'Test 결과 종합'!E$6) -> 0 | F12: =COUNTIFS('01) 메세지 테스트'!$AB$5:$AB$133,'Test 결과 종합'!$C$3,'01) 메세지 테스트'!$AC$5:$AC$133,'Test 결과 종합'!F$6) -> 0 | G12: =COUNTIFS('01) 메세지 테스트'!$AB$5:$AB$133,'Test 결과 종합'!$C$3,'01) 메세지 테스트'!$AC$5:$AC$133,'Test 결과 종합'!G$6) -> 0 | H12: =MAX('01) 메세지 테스트'!$B$5:$B$133)-COUNTIF('01) 메세지 테스트'!AC5:AC133,"N/A") -> 34 | I12: =K12 -> 0 | J12: =COUNTIFS('01) 메세지 테스트'!$AC$5:$AC$133,'Test 결과 종합'!J$6) -> 0 | K12: =IF(J12=0,0,J12/H12) -> 0 | L12: =COUNTIFS('01) 메세지 테스트'!$AC$5:$AC$133,'Test 결과 종합'!L$6) -> 0 | M12: =IF(L12=0,0,L12/H12) -> 0 | N12: =COUNTIFS('01) 메세지 테스트'!$AC$5:$AC$133,'Test 결과 종합'!N$6) -> 0 | O12: =IF(N12=0,0,N12/H12) -> 0
C13: Unit#6 | D13: =COUNTIFS('01) 메세지 테스트'!$AF$5:$AF$133,'Test 결과 종합'!$C$3) -> 0 | E13: =COUNTIFS('01) 메세지 테스트'!$AF$5:$AF$133,'Test 결과 종합'!$C$3,'01) 메세지 테스트'!$AG$5:$AG$133,'Test 결과 종합'!E$6) -> 0 | F13: =COUNTIFS('01) 메세지 테스트'!$AF$5:$AF$133,'Test 결과 종합'!$C$3,'01) 메세지 테스트'!$AG$5:$AG$133,'Test 결과 종합'!F$6) -> 0 | G13: =COUNTIFS('01) 메세지 테스트'!$AF$5:$AF$133,'Test 결과 종합'!$C$3,'01) 메세지 테스트'!$AG$5:$AG$133,'Test 결과 종합'!G$6) -> 0 | H13: =MAX('01) 메세지 테스트'!$B$5:$B$133)-COUNTIF('01) 메세지 테스트'!AG5:AG133,"N/A") -> 34 | I13: =K13 -> 0 | J13: =COUNTIFS('01) 메세지 테스트'!$AG$5:$AG$133,'Test 결과 종합'!J$6) -> 0 | K13: =IF(J13=0,0,J13/H13) -> 0 | L13: =COUNTIFS('01) 메세지 테스트'!$AG$5:$AG$133,'Test 결과 종합'!L$6) -> 0 | M13: =IF(L13=0,0,L13/H13) -> 0 | N13: =COUNTIFS('01) 메세지 테스트'!$AG$5:$AG$133,'Test 결과 종합'!N$6) -> 0 | O13: =IF(N13=0,0,N13/H13) -> 0
C14: Unit#7 | D14: =COUNTIFS('01) 메세지 테스트'!$AJ$5:$AJ$133,'Test 결과 종합'!$C$3) -> 0 | E14: =COUNTIFS('01) 메세지 테스트'!$AJ$5:$AJ$133,'Test 결과 종합'!$C$3,'01) 메세지 테스트'!$AK$5:$AK$133,'Test 결과 종합'!E$6) -> 0 | F14: =COUNTIFS('01) 메세지 테스트'!$AJ$5:$AJ$133,'Test 결과 종합'!$C$3,'01) 메세지 테스트'!$AK$5:$AK$133,'Test 결과 종합'!F$6) -> 0 | G14: =COUNTIFS('01) 메세지 테스트'!$AJ$5:$AJ$133,'Test 결과 종합'!$C$3,'01) 메세지 테스트'!$AK$5:$AK$133,'Test 결과 종합'!G$6) -> 0 | H14: =MAX('01) 메세지 테스트'!$B$5:$B$133)-COUNTIF('01) 메세지 테스트'!AK5:AK133,"N/A") -> 34 | I14: =K14 -> 0 | J14: =COUNTIFS('01) 메세지 테스트'!$AK$5:$AK$133,'Test 결과 종합'!J$6) -> 0 | K14: =IF(J14=0,0,J14/H14) -> 0 | L14: =COUNTIFS('01) 메세지 테스트'!$AK$5:$AK$133,'Test 결과 종합'!L$6) -> 0 | M14: =IF(L14=0,0,L14/H14) -> 0 | N14: =COUNTIFS('01) 메세지 테스트'!$AK$5:$AK$133,'Test 결과 종합'!N$6) -> 0 | O14: =IF(N14=0,0,N14/H14) -> 0
B15: 시나리오 테스트 | C15: Unit#1 | D15: =COUNTIFS('02) 시나리오 테스트'!$N$5:$N$67,'Test 결과 종합'!$C$3) -> 0 | E15: =COUNTIFS('02) 시나리오 테스트'!$N$5:$N$67,'Test 결과 종합'!$C$3,'02) 시나리오 테스트'!$O$5:$O$67,'Test 결과 종합'!E$6) -> 0 | F15: =COUNTIFS('02) 시나리오 테스트'!$N$5:$N$67,'Test 결과 종합'!$C$3,'02) 시나리오 테스트'!$O$5:$O$67,'Test 결과 종합'!F$6) -> 0 | G15: =COUNTIFS('02) 시나리오 테스트'!$N$5:$N$67,'Test 결과 종합'!$D$3,'02) 시나리오 테스트'!$O$5:$O$67,'Test 결과 종합'!G$6) -> 0 | H15: =MAX('02) 시나리오 테스트'!$B$5:$B$67)-COUNTIF('02) 시나리오 테스트'!O5:O64,"N/A") -> 22 | I15: =K15 -> 0 | J15: =COUNTIFS('02) 시나리오 테스트'!$O$5:$O$67,'Test 결과 종합'!J$6) -> 0 | K15: =IF(J15=0,0,J15/H15) -> 0 | L15: =COUNTIFS('02) 시나리오 테스트'!$O$5:$O$67,'Test 결과 종합'!L$6) -> 0 | M15: =IF(L15=0,0,L15/H15) -> 0 | N15: =COUNTIFS('02) 시나리오 테스트'!$O$5:$O$67,'Test 결과 종합'!N$6) -> 0 | O15: =IF(N15=0,0,N15/H15) -> 0
C16: Unit#2 | D16: =COUNTIFS('02) 시나리오 테스트'!$Q$5:$Q$67,'Test 결과 종합'!$C$3) -> 0 | E16: =COUNTIFS('02) 시나리오 테스트'!$Q$5:$Q$67,'Test 결과 종합'!$C$3,'02) 시나리오 테스트'!$R$5:$R$67,'Test 결과 종합'!E$6) -> 0 | F16: =COUNTIFS('02) 시나리오 테스트'!$Q$5:$Q$67,'Test 결과 종합'!$C$3,'02) 시나리오 테스트'!$R$5:$R$67,'Test 결과 종합'!F$6) -> 0 | G16: =COUNTIFS('02) 시나리오 테스트'!$Q$5:$Q$67,'Test 결과 종합'!$C$3,'02) 시나리오 테스트'!$R$5:$R$67,'Test 결과 종합'!G$6) -> 0 | H16: =MAX('02) 시나리오 테스트'!$B$5:$B$67)-COUNTIF('02) 시나리오 테스트'!R5:R64,"N/A") -> 22 | I16: =K16 -> 0 | J16: =COUNTIFS('02) 시나리오 테스트'!$R$5:$R$67,'Test 결과 종합'!J$6) -> 0 | K16: =IF(J16=0,0,J16/H16) -> 0 | L16: =COUNTIFS('02) 시나리오 테스트'!$R$5:$R$67,'Test 결과 종합'!L$6) -> 0 | M16: =IF(L16=0,0,L16/H16) -> 0 | N16: =COUNTIFS('02) 시나리오 테스트'!$R$5:$R$67,'Test 결과 종합'!N$6) -> 0 | O16: =IF(N16=0,0,N16/H16) -> 0
C17: Unit#3 | D17: =COUNTIFS('02) 시나리오 테스트'!$T$5:$T$67,'Test 결과 종합'!$C$3) -> 0 | E17: =COUNTIFS('02) 시나리오 테스트'!$T$5:$T$67,'Test 결과 종합'!$C$3,'02) 시나리오 테스트'!$U$5:$U$67,'Test 결과 종합'!E$6) -> 0 | F17: =COUNTIFS('02) 시나리오 테스트'!$T$5:$T$67,'Test 결과 종합'!$C$3,'02) 시나리오 테스트'!$U$5:$U$67,'Test 결과 종합'!F$6) -> 0 | G17: =COUNTIFS('02) 시나리오 테스트'!$T$5:$T$67,'Test 결과 종합'!$C$3,'02) 시나리오 테스트'!$U$5:$U$67,'Test 결과 종합'!G$6) -> 0 | H17: =MAX('02) 시나리오 테스트'!$B$5:$B$67)-COUNTIF('02) 시나리오 테스트'!U5:U64,"N/A") -> 22 | I17: =K17 -> 0 | J17: =COUNTIFS('02) 시나리오 테스트'!$U$5:$U$67,'Test 결과 종합'!J$6) -> 0 | K17: =IF(J17=0,0,J17/H17) -> 0 | L17: =COUNTIFS('02) 시나리오 테스트'!$U$5:$U$67,'Test 결과 종합'!L$6) -> 0 | M17: =IF(L17=0,0,L17/H17) -> 0 | N17: =COUNTIFS('02) 시나리오 테스트'!$U$5:$U$67,'Test 결과 종합'!N$6) -> 0 | O17: =IF(N17=0,0,N17/H17) -> 0
C18: Unit#4 | D18: =COUNTIFS('02) 시나리오 테스트'!$W$5:$W$67,'Test 결과 종합'!$C$3) -> 0 | E18: =COUNTIFS('02) 시나리오 테스트'!$W$5:$W$67,'Test 결과 종합'!$C$3,'02) 시나리오 테스트'!$X$5:$X$67,'Test 결과 종합'!E$6) -> 0 | F18: =COUNTIFS('02) 시나리오 테스트'!$W$5:$W$67,'Test 결과 종합'!$C$3,'02) 시나리오 테스트'!$X$5:$X$67,'Test 결과 종합'!F$6) -> 0 | G18: =COUNTIFS('02) 시나리오 테스트'!$W$5:$W$67,'Test 결과 종합'!$C$3,'02) 시나리오 테스트'!$X$5:$X$67,'Test 결과 종합'!G$6) -> 0 | H18: =MAX('02) 시나리오 테스트'!$B$5:$B$67)-COUNTIF('02) 시나리오 테스트'!X5:X64,"N/A") -> 22 | I18: =K18 -> 0 | J18: =COUNTIFS('02) 시나리오 테스트'!$X$5:$X$67,'Test 결과 종합'!J$6) -> 0 | K18: =IF(J18=0,0,J18/H18) -> 0 | L18: =COUNTIFS('02) 시나리오 테스트'!$X$5:$X$67,'Test 결과 종합'!L$6) -> 0 | M18: =IF(L18=0,0,L18/H18) -> 0 | N18: =COUNTIFS('02) 시나리오 테스트'!$X$5:$X$67,'Test 결과 종합'!N$6) -> 0 | O18: =IF(N18=0,0,N18/H18) -> 0
C19: Unit#5 | D19: =COUNTIFS('02) 시나리오 테스트'!$Z$5:$Z$67,'Test 결과 종합'!$C$3) -> 0 | E19: =COUNTIFS('02) 시나리오 테스트'!$Z$5:$Z$67,'Test 결과 종합'!$C$3,'02) 시나리오 테스트'!$AA$5:$AA$67,'Test 결과 종합'!E$6) -> 0 | F19: =COUNTIFS('02) 시나리오 테스트'!$Z$5:$Z$67,'Test 결과 종합'!$C$3,'02) 시나리오 테스트'!$AA$5:$AA$67,'Test 결과 종합'!F$6) -> 0 | G19: =COUNTIFS('02) 시나리오 테스트'!$Z$5:$Z$67,'Test 결과 종합'!$C$3,'02) 시나리오 테스트'!$AA$5:$AA$67,'Test 결과 종합'!G$6) -> 0 | H19: =MAX('02) 시나리오 테스트'!$B$5:$B$67)-COUNTIF('02) 시나리오 테스트'!AA5:AA64,"N/A") -> 22 | I19: =K19 -> 0 | J19: =COUNTIFS('02) 시나리오 테스트'!$AA$5:$AA$67,'Test 결과 종합'!J$6) -> 0 | K19: =IF(J19=0,0,J19/H19) -> 0 | L19: =COUNTIFS('02) 시나리오 테스트'!$AA$5:$AA$67,'Test 결과 종합'!L$6) -> 0 | M19: =IF(L19=0,0,L19/H19) -> 0 | N19: =COUNTIFS('02) 시나리오 테스트'!$AA$5:$AA$67,'Test 결과 종합'!N$6) -> 0 | O19: =IF(N19=0,0,N19/H19) -> 0
C20: Unit#6 | D20: =COUNTIFS('02) 시나리오 테스트'!$AC$5:$AC$67,'Test 결과 종합'!$C$3) -> 0 | E20: =COUNTIFS('02) 시나리오 테스트'!$AC$5:$AC$67,'Test 결과 종합'!$C$3,'02) 시나리오 테스트'!$AD$5:$AD$67,'Test 결과 종합'!E$6) -> 0 | F20: =COUNTIFS('02) 시나리오 테스트'!$AC$5:$AC$67,'Test 결과 종합'!$C$3,'02) 시나리오 테스트'!$AD$5:$AD$67,'Test 결과 종합'!F$6) -> 0 | G20: =COUNTIFS('02) 시나리오 테스트'!$AC$5:$AC$67,'Test 결과 종합'!$C$3,'02) 시나리오 테스트'!$AD$5:$AD$67,'Test 결과 종합'!G$6) -> 0 | H20: =MAX('02) 시나리오 테스트'!$B$5:$B$67)-COUNTIF('02) 시나리오 테스트'!AD5:AD64,"N/A") -> 22 | I20: =K20+O20 -> 0 | J20: =COUNTIFS('02) 시나리오 테스트'!$AD$5:$AD$67,'Test 결과 종합'!J$6) -> 0 | K20: =IF(J20=0,0,J20/H20) -> 0 | L20: =COUNTIFS('02) 시나리오 테스트'!$AD$5:$AD$67,'Test 결과 종합'!L$6) -> 0 | M20: =IF(L20=0,0,L20/H20) -> 0 | N20: =COUNTIFS('02) 시나리오 테스트'!$AD$5:$AD$67,'Test 결과 종합'!N$6) -> 0 | O20: =IF(N20=0,0,N20/H20) -> 0
C21: Unit#7 | D21: =COUNTIFS('02) 시나리오 테스트'!$AF$5:$AF$67,'Test 결과 종합'!$C$3) -> 0 | E21: =COUNTIFS('02) 시나리오 테스트'!$AF$5:$AF$67,'Test 결과 종합'!$C$3,'02) 시나리오 테스트'!$AG$5:$AG$67,'Test 결과 종합'!E$6) -> 0 | F21: =COUNTIFS('02) 시나리오 테스트'!$AF$5:$AF$67,'Test 결과 종합'!$C$3,'02) 시나리오 테스트'!$AG$5:$AG$67,'Test 결과 종합'!F$6) -> 0 | G21: =COUNTIFS('02) 시나리오 테스트'!$AF$5:$AF$67,'Test 결과 종합'!$C$3,'02) 시나리오 테스트'!$AG$5:$AG$67,'Test 결과 종합'!G$6) -> 0 | H21: =MAX('02) 시나리오 테스트'!$B$5:$B$67)-COUNTIF('02) 시나리오 테스트'!AG5:AG64,"N/A") -> 22 | I21: =K21+O21 -> 0 | J21: =COUNTIFS('02) 시나리오 테스트'!$AG$5:$AG$67,'Test 결과 종합'!J$6) -> 0 | K21: =IF(J21=0,0,J21/H21) -> 0 | L21: =COUNTIFS('02) 시나리오 테스트'!$AG$5:$AG$67,'Test 결과 종합'!L$6) -> 0 | M21: =IF(L21=0,0,L21/H21) -> 0 | N21: =COUNTIFS('02) 시나리오 테스트'!$AG$5:$AG$67,'Test 결과 종합'!N$6) -> 0 | O21: =IF(N21=0,0,N21/H21) -> 0
B22: Machine Total | C22: Unit#1 | H22: =H8+H15 -> 56 | I22: =J22/H22 -> 0 | J22: =J8+J15 -> 0 | K22: =IF(J22=0,0,J22/H22) -> 0 | L22: =L8+L15 -> 0 | M22: =IF(L22=0,0,L22/H22) -> 0 | N22: =N8+N15 -> 0 | O22: =IF(N22=0,0,N22/H22) -> 0
C23: Unit#2 | H23: =H9+H16 -> 56 | I23: =J23/H23 -> 0 | J23: =J9+J16 -> 0 | K23: =IF(J23=0,0,J23/H23) -> 0 | L23: =L9+L16 -> 0 | M23: =IF(L23=0,0,L23/H23) -> 0 | N23: =N9+N16 -> 0 | O23: =IF(N23=0,0,N23/H23) -> 0
C24: Unit#3 | H24: =H10+H17 -> 56 | I24: =J24/H24 -> 0 | J24: =J10+J17 -> 0 | K24: =IF(J24=0,0,J24/H24) -> 0 | L24: =L10+L17 -> 0 | M24: =IF(L24=0,0,L24/H24) -> 0 | N24: =N10+N17 -> 0 | O24: =IF(N24=0,0,N24/H24) -> 0
C25: Unit#4 | H25: =H11+H18 -> 56 | I25: =J25/H25 -> 0 | J25: =J11+J18 -> 0 | K25: =IF(J25=0,0,J25/H25) -> 0 | L25: =L11+L18 -> 0 | M25: =IF(L25=0,0,L25/H25) -> 0 | N25: =N11+N18 -> 0 | O25: =IF(N25=0,0,N25/H25) -> 0
C26: Unit#5 | H26: =H12+H19 -> 56 | I26: =(J12+J19)/H26 -> 0 | J26: =J12+J19 -> 0 | K26: =IF(J26=0,0,J26/H26) -> 0 | L26: =L12+L19 -> 0 | M26: =IF(L26=0,0,L26/H26) -> 0 | N26: =N12+N19 -> 0 | O26: =IF(N26=0,0,N26/H26) -> 0
C27: Unit#6 | H27: =H13+H20 -> 56 | I27: =K27 -> 0 | J27: =J13+J20 -> 0 | K27: =IF(J27=0,0,J27/H27) -> 0 | L27: =L13+L20 -> 0 | M27: =IF(L27=0,0,L27/H27) -> 0 | N27: =N13+N20 -> 0 | O27: =IF(N27=0,0,N27/H27) -> 0
C28: Unit#7 | H28: =H14+H21 -> 56 | I28: =K28 -> 0 | J28: =J14+J21 -> 0 | K28: =IF(J28=0,0,J28/H28) -> 0 | L28: =L14+L21 -> 0 | M28: =IF(L28=0,0,L28/H28) -> 0 | N28: =N14+N21 -> 0 | O28: =IF(N28=0,0,N28/H28) -> 0
B29: Line Total | D29: =SUM(D8:D21) -> 0 | E29: =SUM(E8:E21) -> 0 | F29: =SUM(F8:F21) -> 0 | G29: =SUM(G8:G21) -> 0 | H29: =SUM(H8:H21) -> 392 | I29: =K29 -> 0 | J29: =SUM(J8:J21) -> 0 | K29: =IF(J29=0,0,J29/H29) -> 0 | L29: =SUM(L8:L21) -> 0 | M29: =IF(L29=0,0,L29/H29) -> 0 | N29: =SUM(N8:N21) -> 0 | O29: =IF(N29=0,0,N29/H29) -> 0
B31: 테스트 개요 | D31: - 테스트 일정 : 2026.xx.xx~2026.xx.xx (테스트 N일차 [2026.xx.xx])
D32: - 테스트 담당자
E33: 업무 구분 | H33: 소속 (회사명) | J33: 성명 (이름 직급) | L33: 전화번호
D42: - 테스트 환경
E43: 구분 | H43: 설비 | J43: EIF | L43: GMES | N43: GRMS | P43: 비고
E44: 테스트 환경 | H44: 양산 서버에 연결 | J44: 양산 서버 | L44: 개발서버 | N44: 개발서버
E45: 테스트 후 환경 | H45: 양산 서버에 연결 | J45: 양산 서버 | L45: 양산 서버 | N45: 양산서버
B47: 종 합 의 견 | D47: [ Test 종합 의견 ] - Online 및 Tray Sceanario 테스트 - 잔건 진행 - WJ Cleaning RMS 현장 TEST 대기 - Plasma Cleaner RMS 현장 TEST 완료 (업체 프로그램 특성상 지정파라미터 사용불가) [ 향후 계획 ] - [ 지원 요청 사항 ]
B48: 테스트 전 Check List
E49: Check List | L49: Contect Point | N49: Rusult
E50: LAN Cable 연결 여부 | L50: Maker | N50: Y
E51: 설비 IP Address & Port No. Setting 여부 | L51: Maker | N51: Y
E52: 설비 제어담당자/통역 Arrange 여부 | L52: Maker | N52: Y
...

Sheet 01) 메세지 테스트
A2: ▣ 메시지 테스트
B3: No | C3: Test Case ID | D3: Stream | E3: Function | F3: Direction | G3: Required | H3: Message Name | I3: RPTID | J3: MES BizRule Name | K3: EIF 담당자 | L3: Unit #1 | P3: Unit #2 | T3: Unit #3 | X3: Unit #4 | AB3: Unit #5 | AF3: Unit #6 | AJ3: Unit #7
L4: 날짜 | M4: 판정 | N4: Message Structure (Test Log Copy) | O4: 비고 | P4: 날짜 | Q4: 판정 | R4: Message Structure (Test Log Copy) | S4: 비고 | T4: 날짜 | U4: 판정 | V4: Message Structure (Test Log Copy) | W4: 비고 | X4: 날짜 | Y4: 판정 | Z4: Message Structure (Test Log Copy) | AA4: 비고 | AB4: 날짜 | AC4: 판정 | AD4: Message Structure (Test Log Copy) | AE4: 비고 | AF4: 날짜 | AG4: 판정 | AH4: Message Structure (Test Log Copy) | AI4: 비고 | AJ4: 날짜 | AK4: 판정 | AL4: Message Structure (Test Log Copy) | AM4: 비고
B5: 1 | C5: =IF($B5="","",CONCATENATE("TC-EIF-MSG-",$B5)) -> TC-EIF-MSG-1 | D5: * | E5: 0 | F5: H◀▶E | G5: O | H5: Abort Transaction | I5: - | M5: N/A | Q5: N/A | U5: N/A | Y5: N/A | AC5: N/A | AG5: N/A | AK5: N/A
B6: =IF(OR(M6="-",M6="N/A"),"",COUNTA(M$5:M6)-(COUNTIF((M$5:M6),"-")+COUNTIF((M$5:M6),"N/A"))+COUNTIF((M$5:M6),"")) | C6: =IF($B6="","",CONCATENATE("TC-EIF-MSG-",$B6)) | D6: 1 | H6: Stream1 | L6: - | M6: - | P6: - | Q6: - | T6: - | U6: - | X6: - | Y6: - | AB6: - | AC6: - | AG6: - | AK6: -
B7: =B5+1 -> 2 | C7: =IF($B7="","",CONCATENATE("TC-EIF-MSG-",$B7)) -> TC-EIF-MSG-2 | D7: 1 | E7: 1 | F7: H◀▶E | G7: O | H7: Are You There Request | I7: - | M7: 미실시 | Q7: 미실시 | U7: 미실시 | Y7: 미실시 | AC7: 미실시 | AG7: 미실시 | AK7: 미실시
B8: =B7+1 -> 3 | C8: =IF($B8="","",CONCATENATE("TC-EIF-MSG-",$B8)) -> TC-EIF-MSG-3 | D8: 1 | E8: 2 | F8: H◀▶E | G8: O | H8: Are You There Data | I8: - | M8: 미실시 | Q8: 미실시 | U8: 미실시 | Y8: 미실시 | AC8: 미실시 | AG8: 미실시 | AK8: 미실시
B9: =B8+1 -> 4 | C9: =IF($B9="","",CONCATENATE("TC-EIF-MSG-",$B9)) -> TC-EIF-MSG-4 | D9: 1 | E9: 3 | F9: H▶E | G9: O | H9: Selected Equipment Status Request | I9: - | M9: 미실시 | Q9: 미실시 | U9: 미실시 | Y9: 미실시 | AC9: 미실시 | AG9: 미실시 | AK9: 미실시
B10: =B9+1 -> 5 | C10: =IF($B10="","",CONCATENATE("TC-EIF-MSG-",$B10)) -> TC-EIF-MSG-5 | D10: 1 | E10: 4 | F10: H◀E | G10: O | H10: Selected Equipment Status Data | I10: - | M10: 미실시 | Q10: 미실시 | U10: 미실시 | Y10: 미실시 | AC10: 미실시 | AG10: 미실시 | AK10: 미실시
B11: =IF(OR(M11="-",M11="N/A"),"",COUNTA(M$5:M11)-(COUNTIF((M$5:M11),"-")+COUNTIF((M$5:M11),"N/A"))+COUNTIF((M$5:M11),"")) | C11: =IF($B11="","",CONCATENATE("TC-EIF-MSG-",$B11)) | D11: 2 | H11: Stream2 | L11: - | M11: - | P11: - | Q11: - | T11: - | U11: - | X11: - | Y11: - | AB11: - | AC11: - | AG11: - | AK11: -
B12: =IF(OR(M12="-",M12="N/A"),"",COUNTA(M$5:M12)-(COUNTIF((M$5:M12),"-")+COUNTIF((M$5:M12),"N/A"))+COUNTIF((M$5:M12),"")) -> 5 | C12: =IF($B12="","",CONCATENATE("TC-EIF-MSG-",$B12)) -> TC-EIF-MSG-5 | D12: 2 | E12: 3 | F12: H▶E | G12: O | H12: Link Test Request | I12: - | M12: 미실시 | Q12: 미실시 | U12: 미실시 | Y12: 미실시 | AC12: 미실시 | AG12: 미실시 | AK12: 미실시
B13: =B12+1 -> 6 | C13: =IF($B13="","",CONCATENATE("TC-EIF-MSG-",$B13)) -> TC-EIF-MSG-6 | D13: 2 | E13: 4 | F13: H◀E | G13: O | H13: Link Test Response | I13: - | M13: 미실시 | Q13: 미실시 | U13: 미실시 | Y13: 미실시 | AC13: 미실시 | AG13: 미실시 | AK13: 미실시
B14: =B13+1 -> 7 | C14: =IF($B14="","",CONCATENATE("TC-EIF-MSG-",$B14)) -> TC-EIF-MSG-7 | D14: 2 | E14: 17 | F14: H◀▶E | G14: O | H14: Date and Time Request (DTR) | I14: - | M14: 미실시 | Q14: 미실시 | U14: 미실시 | Y14: 미실시 | AC14: 미실시 | AG14: 미실시 | AK14: 미실시
B15: =B14+1 -> 8 | C15: =IF($B15="","",CONCATENATE("TC-EIF-MSG-",$B15)) -> TC-EIF-MSG-8 | D15: 2 | E15: 18 | F15: H◀▶E | G15: O | H15: Date and Time Data (DTD) | I15: - | M15: 미실시 | Q15: 미실시 | U15: 미실시 | Y15: 미실시 | AC15: 미실시 | AG15: 미실시 | AK15: 미실시
B16: =B15+1 -> 9 | C16: =IF($B16="","",CONCATENATE("TC-EIF-MSG-",$B16)) -> TC-EIF-MSG-9 | D16: 2 | E16: 23 | F16: H▶E | G16: O | H16: Trace Initialize Send (TIS) | I16: - | M16: N/A | Q16: N/A | U16: N/A | Y16: N/A | AC16: N/A | AG16: N/A | AK16: N/A
B17: =B16+1 -> 10 | C17: =IF($B17="","",CONCATENATE("TC-EIF-MSG-",$B17)) -> TC-EIF-MSG-10 | D17: 2 | E17: 24 | F17: H◀E | G17: O | H17: Trace Initialize Acknowledge (TIA) | I17: - | M17: N/A | Q17: N/A | U17: N/A | Y17: N/A | AC17: N/A | AG17: N/A | AK17: N/A
B18: =B17+1 -> 11 | C18: =IF($B18="","",CONCATENATE("TC-EIF-MSG-",$B18)) -> TC-EIF-MSG-11 | D18: 2 | E18: 31 | F18: H▶E | G18: O | H18: Date and Time Set Request | I18: - | M18: 미실시 | Q18: 미실시 | U18: 미실시 | Y18: 미실시 | AC18: 미실시 | AG18: 미실시 | AK18: 미실시
B19: =B18+1 -> 12 | C19: =IF($B19="","",CONCATENATE("TC-EIF-MSG-",$B19)) -> TC-EIF-MSG-12 | D19: 2 | E19: 32 | F19: H◀E | G19: O | H19: Date and Time Set Acknowledge | I19: - | M19: 미실시 | Q19: 미실시 | U19: 미실시 | Y19: 미실시 | AC19: 미실시 | AG19: 미실시 | AK19: 미실시
B20: =B19+1 -> 13 | C20: =IF($B20="","",CONCATENATE("TC-EIF-MSG-",$B20)) -> TC-EIF-MSG-13 | D20: 2 | E20: 49 | F20: H▶E | G20: O | H20: LOT_START | I20: - | M20: N/A | Q20: N/A | U20: N/A | Y20: N/A | AC20: N/A | AG20: N/A | AK20: N/A
B21: =B20+1 -> 14 | C21: =IF($B21="","",CONCATENATE("TC-EIF-MSG-",$B21)) -> TC-EIF-MSG-14 | D21: 2 | E21: 49 | F21: H▶E | G21: O | H21: LOT_ID_FAIL | I21: - | M21: N/A | Q21: N/A | U21: N/A | Y21: N/A | AC21: N/A | AG21: N/A | AK21: N/A
B22: =B21+1 -> 15 | C22: =IF($B22="","",CONCATENATE("TC-EIF-MSG-",$B22)) -> TC-EIF-MSG-15 | D22: 2 | E22: 49 | F22: H▶E | G22: O | H22: NG_LOT_START | I22: - | M22: N/A | Q22: N/A | U22: N/A | Y22: N/A | AC22: N/A | AG22: N/A | AK22: N/A
B23: =B21+1 -> 15 | C23: =IF($B23="","",CONCATENATE("TC-EIF-MSG-",$B23)) -> TC-EIF-MSG-15 | D23: 2 | E23: 49 | F23: H▶E | G23: O | H23: NG_LOT_ID_FAIL | I23: - | M23: N/A | Q23: N/A | U23: N/A | Y23: N/A | AC23: N/A | AG23: N/A | AK23: N/A
B24: =B22+1 -> 16 | C24: =IF($B24="","",CONCATENATE("TC-EIF-MSG-",$B24)) -> TC-EIF-MSG-16 | D24: 2 | E24: 49 | F24: H▶E | G24: O | H24: PRODUCT_ID_FAIL | I24: - | M24: N/A | Q24: N/A | U24: N/A | Y24: N/A | AC24: N/A | AG24: N/A | AK24: N/A
B25: =B24+1 -> 17 | C25: =IF($B25="","",CONCATENATE("TC-EIF-MSG-",$B25)) -> TC-EIF-MSG-17 | D25: 2 | E25: 49 | F25: H▶E | G25: O | H25: PRODUCT_DATA | I25: - | M25: N/A | Q25: N/A | U25: N/A | Y25: N/A | AC25: N/A | AG25: N/A | AK25: N/A
B26: =B25+1 -> 18 | C26: =IF($B26="","",CONCATENATE("TC-EIF-MSG-",$B26)) -> TC-EIF-MSG-18 | D26: 2 | E26: 49 | F26: H▶E | G26: O | H26: SETCODE_IDLE_REASON | I26: - | M26: 미실시 | Q26: 미실시 | U26: 미실시 | Y26: 미실시 | AC26: 미실시 | AG26: 미실시 | AK26: 미실시
B27: =B26+1 -> 19 | C27: =IF($B27="","",CONCATENATE("TC-EIF-MSG-",$B27)) -> TC-EIF-MSG-19 | D27: 2 | E27: 49 | F27: H▶E | G27: O | H27: SETCODE_DOWN_ACTION | I27: - | M27: 미실시 | Q27: 미실시 | U27: 미실시 | Y27: 미실시 | AC27: 미실시 | AG27: 미실시 | AK27: 미실시
B28: =B27+1 -> 20 | C28: =IF($B28="","",CONCATENATE("TC-EIF-MSG-",$B28)) -> TC-EIF-MSG-20 | D28: 2 | E28: 50 | F28: H◀E | G28: O | H28: Enhanced Remote Command Acknowledge | I28: - | M28: 미실시 | Q28: 미실시 | U28: 미실시 | Y28: 미실시 | AC28: 미실시 | AG28: 미실시 | AK28: 미실시
B29: =B28+1 -> 21 | C29: =IF($B29="","",CONCATENATE("TC-EIF-MSG-",$B29)) -> TC-EIF-MSG-21 | D29: 2 | E29: 61 | F29: H◀E | G29: Optional | H29: Idle Reason Code Request | I29: - | M29: 미실시 | Q29: 미실시 | U29: 미실시 | Y29: 미실시 | AC29: 미실시 | AG29: 미실시 | AK29: 미실시
B30: =B29+1 -> 22 | C30: =IF($B30="","",CONCATENATE("TC-EIF-MSG-",$B30)) -> TC-EIF-MSG-22 | D30: 2 | E30: 62 | F30: H▶E | G30: Optional | H30: Idle Reason Code Data | I30: - | M30: 미실시 | Q30: 미실시 | U30: 미실시 | Y30: 미실시 | AC30: 미실시 | AG30: 미실시 | AK30: 미실시
B31: =IF(OR(M31="-",M31="N/A"),"",COUNTA(M$5:M31)-(COUNTIF((M$5:M31),"-")+COUNTIF((M$5:M31),"N/A"))+COUNTIF((M$5:M31),"")) | C31: =IF($B31="","",CONCATENATE("TC-EIF-MSG-",$B31)) | D31: 5 | H31: Stream5 | L31: - | M31: - | P31: - | Q31: - | T31: - | U31: - | X31: - | Y31: - | AB31: - | AC31: - | AG31: - | AK31: -
B32: =B30+1 -> 23 | C32: =IF($B32="","",CONCATENATE("TC-EIF-MSG-",$B32)) -> TC-EIF-MSG-23 | D32: 5 | E32: 1 | F32: H◀E | G32: O | H32: Alarm Report Send | I32: - | M32: 미실시 | Q32: 미실시 | U32: 미실시 | Y32: 미실시 | AC32: 미실시 | AG32: 미실시 | AK32: 미실시
B33: =B32+1 -> 24 | C33: =IF($B33="","",CONCATENATE("TC-EIF-MSG-",$B33)) -> TC-EIF-MSG-24 | D33: 5 | E33: 2 | F33: H▶E | G33: O | H33: Alarm Report Acknowledge | I33: - | M33: 미실시 | Q33: 미실시 | U33: 미실시 | Y33: 미실시 | AC33: 미실시 | AG33: 미실시 | AK33: 미실시
B34: =B33+1 -> 25 | C34: =IF($B34="","",CONCATENATE("TC-EIF-MSG-",$B34)) -> TC-EIF-MSG-25 | D34: 5 | E34: 5 | F34: H▶E | G34: O | H34: List Alarms Request | I34: - | M34: 미실시 | Q34: 미실시 | U34: 미실시 | Y34: 미실시 | AC34: 미실시 | AG34: 미실시 | AK34: 미실시
B35: =B34+1 -> 26 | C35: =IF($B35="","",CONCATENATE("TC-EIF-MSG-",$B35)) -> TC-EIF-MSG-26 | D35: 5 | E35: 6 | F35: H◀E | G35: O | H35: List Alarm Data | I35: - | M35: 미실시 | Q35: 미실시 | U35: 미실시 | Y35: 미실시 | AC35: 미실시 | AG35: 미실시 | AK35: 미실시
B36: =IF(OR(M36="-",M36="N/A"),"",COUNTA(M$5:M36)-(COUNTIF((M$5:M36),"-")+COUNTIF((M$5:M36),"N/A"))+COUNTIF((M$5:M36),"")) | C36: =IF($B36="","",CONCATENATE("TC-EIF-MSG-",$B36)) | D36: 6 | H36: Stream6 | L36: - | M36: - | P36: - | Q36: - | T36: - | U36: - | X36: - | Y36: - | AB36: - | AC36: - | AG36: - | AK36: -
B37: =B35+1 -> 27 | C37: =IF($B37="","",CONCATENATE("TC-EIF-MSG-",$B37)) -> TC-EIF-MSG-27 | D37: 6 | E37: 1 | F37: H◀E | G37: O | H37: Trace Data Send | I37: - | M37: N/A | Q37: N/A | U37: N/A | Y37: N/A | AC37: N/A | AG37: N/A | AK37: N/A
B38: =B37+1 -> 28 | C38: =IF($B38="","",CONCATENATE("TC-EIF-MSG-",$B38)) -> TC-EIF-MSG-28 | D38: 6 | E38: 2 | F38: H▶E | G38: O | H38: Trace Data Acknowledge | I38: - | M38: N/A | Q38: N/A | U38: N/A | Y38: N/A | AC38: N/A | AG38: N/A | AK38: N/A
B39: =B38+1 -> 29 | C39: =IF($B39="","",CONCATENATE("TC-EIF-MSG-",$B39)) -> TC-EIF-MSG-29 | D39: 6 | E39: 11 | F39: H◀E | G39: O | H39: Control State Change Report | I39: 10101 | M39: 미실시 | Q39: 미실시 | U39: 미실시 | Y39: 미실시 | AC39: 미실시 | AG39: 미실시 | AK39: 미실시
B40: =B39+1 -> 30 | C40: =IF($B40="","",CONCATENATE("TC-EIF-MSG-",$B40)) -> TC-EIF-MSG-30 | D40: 6 | E40: 11 | F40: H◀E | G40: O | H40: Equipment State Change Report | I40: 10102 | M40: 미실시 | Q40: 미실시 | U40: 미실시 | Y40: 미실시 | AC40: 미실시 | AG40: 미실시 | AK40: 미실시
B41: =B40+1 -> 31 | C41: =IF($B41="","",CONCATENATE("TC-EIF-MSG-",$B41)) -> TC-EIF-MSG-31 | D41: 6 | E41: 11 | F41: H◀E | G41: O | H41: Lot ID Report | I41: 20106 | M41: N/A | Q41: N/A | U41: N/A | Y41: N/A | AC41: N/A | AG41: N/A | AK41: N/A
...

Sheet 02) 시나리오 테스트
A2: ▣ 시나리오 테스트
B3: No. | C3: Test Case ID | D3: Test Case | E3: Test Process Description | F3: Name of Function | G3: Sx,Fy | H3: CEID | I3: Required | J3: 적용 Lv. | K3: Remark | M3: EIF담당자 | N3: Unit #1 | Q3: Unit #2 | T3: Unit #3 | W3: Unit #4 | Z3: Unit #5 | AC3: Unit #6 | AF3: Unit #7
N4: 날짜 | O4: 판정 | P4: 비고 | Q4: 날짜 | R4: 판정 | S4: 비고 | T4: 날짜 | U4: 판정 | V4: 비고 | W4: 날짜 | X4: 판정 | Y4: 비고 | Z4: 날짜 | AA4: 판정 | AB4: 비고 | AC4: 날짜 | AD4: 판정 | AE4: 비고 | AF4: 날짜 | AG4: 판정 | AH4: 비고
B5: =IF(OR(O5="-",O5="N/A"),"",COUNTA(O$5:O5)-(COUNTIF((O$5:O5),"-")+COUNTIF((O$5:O5),"N/A"))+COUNTIF((O$5:O5),"")) | C5: =IF($B5="","",CONCATENATE("TC-EIF-SCN-",$B5)) | D5: 통신 연결 Test | O5: - | R5: - | U5: - | X5: - | AA5: - | AD5: - | AG5: -
B6: =IF(OR(O6="-",O6="N/A"),"",COUNTA(O$5:O6)-(COUNTIF((O$5:O6),"-")+COUNTIF((O$5:O6),"N/A"))+COUNTIF((O$5:O6),"")) | C6: =IF($B6="","",CONCATENATE("TC-EIF-SCN-",$B6)) | D6: 1. On-Line Identification | O6: - | R6: - | U6: - | X6: - | AA6: - | AD6: - | AG6: -
B7: 1 | C7: =IF($B7="","",CONCATENATE("TC-EIF-SCN-",$B7)) -> TC-EIF-SCN-1 | D7: 1.1 Are You There Request | E7: 1. Host에서 Are You There 전송 2. 설비는 Online Data 응답 | F7: 1. Are You There | G7: S1F1 | H7: - | I7: O | J7: Lv.1 | O7: 미실시 | R7: 미실시 | U7: 미실시 | X7: 미실시 | AA7: 미실시 | AD7: 미실시 | AG7: 미실시
B8: =B7+1 -> 2 | C8: =IF($B8="","",CONCATENATE("TC-EIF-SCN-",$B8)) -> TC-EIF-SCN-2 | D8: 1.2 Are You There Request | E8: 1. 설비에서 Are You There 전송 2. Host는 Online Data 응답 | F8: 1. Are You There | G8: S1F1 | H8: - | I8: O | J8: Lv.1 | O8: 미실시 | R8: 미실시 | U8: 미실시 | X8: 미실시 | AA8: 미실시 | AD8: 미실시 | AG8: 미실시
B9: =B8+1 -> 3 | C9: =IF($B9="","",CONCATENATE("TC-EIF-SCN-",$B9)) -> TC-EIF-SCN-3 | D9: 1.3 Selected Equipment Status Request | E9: 1. 설비에 설비상태 요청 2. 요청된 설비의 상태 응답 | F9: 1. Selected Equipment Status Request | G9: S1F3 | H9: - | I9: O | J9: Lv.1 | O9: 미실시 | R9: 미실시 | U9: 미실시 | X9: 미실시 | AA9: 미실시 | AD9: 미실시 | AG9: 미실시
B10: =IF(OR(O10="-",O10="N/A"),"",COUNTA(O$5:O10)-(COUNTIF((O$5:O10),"-")+COUNTIF((O$5:O10),"N/A"))+COUNTIF((O$5:O10),"")) | C10: =IF($B10="","",CONCATENATE("TC-EIF-SCN-",$B10)) | D10: 2 Time Synchronization | O10: - | R10: - | U10: - | X10: - | AA10: - | AD10: - | AG10: -
B11: =B9+1 -> 4 | C11: =IF($B11="","",CONCATENATE("TC-EIF-SCN-",$B11)) -> TC-EIF-SCN-4 | D11: 2.1 Link Test Request | E11: 1. Link Test | F11: 1. Link Test Request | G11: S2F3 | H11: - | I11: O | J11: Lv.1 | O11: 미실시 | R11: 미실시 | U11: 미실시 | X11: 미실시 | AA11: 미실시 | AD11: 미실시 | AG11: 미실시
B12: =B11+1 -> 5 | C12: =IF($B12="","",CONCATENATE("TC-EIF-SCN-",$B12)) -> TC-EIF-SCN-5 | D12: 2.2 Date Time Request | E12: 1. 설비에서 Host로 현재 날짜 및 시간 정보를 요청함. 2. Host는 현재 날짜와 시간을 전송함. | F12: 1. Date and Time Request | G12: S2F17 | H12: - | I12: O | J12: Lv.1 | O12: 미실시 | R12: 미실시 | U12: 미실시 | X12: 미실시 | AA12: 미실시 | AD12: 미실시 | AG12: 미실시
B13: =B12+1 -> 6 | C13: =IF($B13="","",CONCATENATE("TC-EIF-SCN-",$B13)) -> TC-EIF-SCN-6 | D13: 2.3 Time Synchronization Data Request By Host | E13: Host에서 설비로 현재 날짜 및 시간 정보를 전송함. - 12 of digits(Default) : YYMMDDhhmmss | F13: 1. Date and Time Set Request | G13: S2F31 | H13: - | I13: O | J13: Lv.1 | O13: 미실시 | R13: 미실시 | U13: 미실시 | X13: 미실시 | AA13: 미실시 | AD13: 미실시 | AG13: 미실시
B14: =IF(OR(O14="-",O14="N/A"),"",COUNTA(O$5:O14)-(COUNTIF((O$5:O14),"-")+COUNTIF((O$5:O14),"N/A"))+COUNTIF((O$5:O14),"")) | C14: =IF($B14="","",CONCATENATE("TC-EIF-SCN-",$B14)) | D14: 3 Alarm Management | O14: - | R14: - | U14: - | X14: - | AA14: - | AD14: - | AG14: -
B15: =B13+1 -> 7 | C15: =IF($B15="","",CONCATENATE("TC-EIF-SCN-",$B15)) -> TC-EIF-SCN-7 | D15: 3.1 Alarm Set(=발생) / Reset(=해제) Report | E15: 설비는 현재 Enabled Alarm이 발생하거나 해제 될 경우, 이를 Host로 보고함. | F15: 1. Alarm Report Send | G15: S5F1 | H15: - | I15: O | J15: Lv.1 | O15: 미실시 | R15: 미실시 | U15: 미실시 | X15: 미실시 | AA15: 미실시 | AD15: 미실시 | AG15: 미실시
B16: =B15+1 -> 8 | C16: =IF($B16="","",CONCATENATE("TC-EIF-SCN-",$B16)) -> TC-EIF-SCN-8 | D16: 3.2 List Alarms Request | E16: List Alarms Request | F16: 1. List Alarms Request | G16: S5F5 | H16: - | I16: Optional | J16: Lv.1 | O16: 미실시 | R16: 미실시 | U16: 미실시 | X16: 미실시 | AA16: 미실시 | AD16: 미실시 | AG16: 미실시
B17: =IF(OR(O17="-",O17="N/A"),"",COUNTA(O$5:O17)-(COUNTIF((O$5:O17),"-")+COUNTIF((O$5:O17),"N/A"))+COUNTIF((O$5:O17),"")) | C17: =IF($B17="","",CONCATENATE("TC-EIF-SCN-",$B17)) | D17: 4. Remote Control | O17: - | R17: - | U17: - | X17: - | AA17: - | AD17: - | AG17: -
B18: =B16+1 -> 9 | C18: =IF($B18="","",CONCATENATE("TC-EIF-SCN-",$B18)) -> TC-EIF-SCN-9 | D18: 4.1 LOT_START | E18: Common : TIME,PROCID,,MODEL,LOTID,RECIPEID,TOTALQTY,OPERATORID | F18: 1. Enhanced Host Command Send | G18: S2F49 | H18: - | I18: O | J18: Lv.1 | O18: N/A | R18: N/A | U18: N/A | X18: N/A | AA18: N/A | AD18: N/A | AG18: N/A
B19: =B18+1 -> 10 | C19: =IF($B19="","",CONCATENATE("TC-EIF-SCN-",$B19)) -> TC-EIF-SCN-10 | D19: 4.2 LOT_ID_FAIL | E19: Common : TIME ,LOTID, RECIPEID, OPERATORID Result : RESULT (n=2) CODE, TEXT | F19: 1. Enhanced Host Command Send | G19: S2F49 | H19: - | I19: O | J19: Lv.1 | O19: N/A | R19: N/A | U19: N/A | X19: N/A | AA19: N/A | AD19: N/A | AG19: N/A
B20: =B19+1 -> 11 | C20: =IF($B20="","",CONCATENATE("TC-EIF-SCN-",$B20)) -> TC-EIF-SCN-11 | D20: 4.3 NG_LOT_START | E20: Common : TIME, PROCID, MODEL, LOTID, RECIPEID, TOTALQTY, OPERATORID | F20: 1. Enhanced Host Command Send | G20: S2F49 | H20: - | I20: O | J20: Lv.1 | O20: N/A | R20: N/A | U20: N/A | X20: N/A | AA20: N/A | AD20: N/A | AG20: N/A
B21: =B20+1 -> 12 | C21: =IF($B21="","",CONCATENATE("TC-EIF-SCN-",$B21)) -> TC-EIF-SCN-12 | D21: 4.4 NG_LOT_ID_FAIL | E21: Common : TIME, LOTID, RECIPEID, OPERATORID Result : RESULT (n=2) CODE, TEXT | F21: 1. Enhanced Host Command Send | G21: S2F49 | H21: - | I21: O | J21: Lv.1 | O21: N/A | R21: N/A | U21: N/A | X21: N/A | AA21: N/A | AD21: N/A | AG21: N/A
B22: =B21+1 -> 13 | C22: =IF($B22="","",CONCATENATE("TC-EIF-SCN-",$B22)) -> TC-EIF-SCN-13 | D22: 4.5 PRODUCT_ID_FAIL | E22: Common : TIME, LOTID, RECIPEID, OPERATORID Result : RESULT (n=2) MODULEID, CODE, TEXT | F22: 1. Enhanced Host Command Send | G22: S2F49 | H22: - | I22: O | J22: Lv.1 | O22: N/A | R22: N/A | U22: N/A | X22: N/A | AA22: N/A | AD22: N/A | AG22: N/A
B23: =B22+1 -> 14 | C23: =IF($B23="","",CONCATENATE("TC-EIF-SCN-",$B23)) -> TC-EIF-SCN-14 | D23: 4.6 PRODUCT_DATA | E23: Common : TIME, LOTID, PROCID, MODEL, MODULEID, RESULT, DETAIL, OPERATORID | F23: 1. Enhanced Host Command Send | G23: S2F49 | H23: - | I23: O | J23: Lv.1 | O23: N/A | R23: N/A | U23: N/A | X23: N/A | AA23: N/A | AD23: N/A | AG23: N/A
B24: =B23+1 -> 15 | C24: =IF($B24="","",CONCATENATE("TC-EIF-SCN-",$B24)) -> TC-EIF-SCN-15 | D24: 4.7 SETCODE_IDLE_REASON | E24: Online Scenario 해당시점에 Idle Reason Code 전송 Common : TIME Idle Reason Code List : IDLEREASONCODELIST, IDLEREASONINFO, CPNAME, CPVALUE | F24: 1. Enhanced Host Command Send | G24: S2F49 | H24: - | I24: O | J24: Lv.1 | O24: 미실시 | R24: 미실시 | U24: 미실시 | X24: 미실시 | AA24: 미실시 | AD24: 미실시 | AG24: 미실시
B25: =B24+1 -> 16 | C25: =IF($B25="","",CONCATENATE("TC-EIF-SCN-",$B25)) -> TC-EIF-SCN-16 | D25: 4.8 SETCODE_DOWN_ACTION | E25: Online Scenario 해당시점에 Down Action Code 전송 Common : TIME, OPERATORID Down Action Code List : DOWNACTIONCODELIST, DOWNACTIONINFO, CPNAME, CPVALUE | F25: 1. Enhanced Host Command Send | G25: S2F49 | H25: - | I25: O | J25: Lv.1 | O25: 미실시 | R25: 미실시 | U25: 미실시 | X25: 미실시 | AA25: 미실시 | AD25: 미실시 | AG25: 미실시
B26: =IF(OR(O26="-",O26="N/A"),"",COUNTA(O$5:O26)-(COUNTIF((O$5:O26),"-")+COUNTIF((O$5:O26),"N/A"))+COUNTIF((O$5:O26),"")) | C26: =IF($B26="","",CONCATENATE("TC-EIF-SCN-",$B26)) | D26: 5. Data Collection | O26: - | R26: - | U26: - | X26: - | AA26: - | AD26: - | AG26: -
B27: =B25+1 -> 17 | C27: =IF($B27="","",CONCATENATE("TC-EIF-SCN-",$B27)) -> TC-EIF-SCN-17 | D27: 5.1 Collection Event Occurs on the Equipment | E27: 1. 설비는 Event 발생 시 정의된 Structure에 따라 Host로 해당 Event를 보고함. | F27: 1. Event Report Send | G27: S6F11 | H27: - | I27: O | J27: Lv.1 | O27: N/A | R27: N/A | U27: N/A | X27: N/A | AA27: N/A | AD27: N/A | AG27: N/A
B28: =B27+1 -> 18 | C28: =IF($B28="","",CONCATENATE("TC-EIF-SCN-",$B28)) -> TC-EIF-SCN-18 | D28: 5.2 Trace Data Collection | E28: 1. DSPER : Sampling 주기 (초단위) 2. REPGSZ : Sampling 주기에 따른 설정 변수 값을 Report Group Size 만큼 누적하여 한번에 보고하는 누적 갯수 3. TOTSMP : Number of samples to be taken during a complete trace period. 0 = 현재 진행되는 Trace를 종료시킴. 4. TRID : 현재 진행되는 TRID 와 같은 TRID로 다시 설비에 통보하면 진행되던 Trace는 종료되고 새로운 Trace가 진행됨. | F28: 1. Trace Initialize Send 2. Trace Data Send 3. Trace Initialize Send (End) | G28: S2F23 S6F1 S2F23 | H28: - | I28: Optional | J28: Lv.3 | O28: N/A | R28: N/A | U28: N/A | X28: N/A | AA28: N/A | AD28: N/A | AG28: N/A
B29: =IF(OR(O29="-",O29="N/A"),"",COUNTA(O$5:O29)-(COUNTIF((O$5:O29),"-")+COUNTIF((O$5:O29),"N/A"))+COUNTIF((O$5:O29),"")) | C29: =IF($B29="","",CONCATENATE("TC-EIF-SCN-",$B29)) | D29: 6. Terminal Services | O29: - | R29: - | U29: - | X29: - | AA29: - | AD29: - | AG29: -
B30: =B28+1 -> 19 | C30: =IF($B30="","",CONCATENATE("TC-EIF-SCN-",$B30)) -> TC-EIF-SCN-19 | D30: 6.1 Host sends information to an equipment’s display device | E30: 1. Host에서 설비로 Terminal Message를 전송함. 2. 설비는 Terminal Message를 화면에 표시하고, 수신한 Terminal Message 이력 관리함. 3. 설비에 Terminal Message 입력창이 있을 경우, 작업자는 Message 입력 후 Host로 전송 가능함. | F30: 1. Terminal Display, Single 2. Terminal Request | G30: S10F3 S10F1 | H30: 90101 | I30: O | J30: Lv.1 | O30: 미실시 | R30: 미실시 | U30: 미실시 | X30: 미실시 | AA30: 미실시 | AD30: 미실시 | AG30: 미실시
B31: =B30+1 -> 20 | C31: =IF($B31="","",CONCATENATE("TC-EIF-SCN-",$B31)) -> TC-EIF-SCN-20 | D31: 6.2 Operator sends information to host | E31: 1. 설비에서 Host로 Terminal Message를 전송함. 2. Host는 설비로 응답함. | F31: 1. Terminal Request 2. Terminal Display, Single | G31: S10F1 S10F3 | I31: O | J31: Lv.1 | O31: 미실시 | R31: 미실시 | U31: 미실시 | X31: 미실시 | AA31: 미실시 | AD31: 미실시 | AG31: 미실시
B32: =IF(OR(O32="-",O32="N/A"),"",COUNTA(O$5:O32)-(COUNTIF((O$5:O32),"-")+COUNTIF((O$5:O32),"N/A"))+COUNTIF((O$5:O32),"")) | C32: =IF($B32="","",CONCATENATE("TC-EIF-SCN-",$B32)) | D32: 7. Control | O32: - | R32: - | U32: - | X32: - | AA32: - | AD32: - | AG32: -
B33: =B31+1 -> 21 | C33: =IF($B33="","",CONCATENATE("TC-EIF-SCN-",$B33)) -> TC-EIF-SCN-21 | D33: 7.1 Control State Change Report | E33: Control State 변경되면 보고 1 : Online / 2 : Offine | F33: Control State Change Report | G33: S6F11 | H33: 10101 | I33: O | J33: Lv.1 | O33: 미실시 | R33: 미실시 | U33: 미실시 | X33: 미실시 | AA33: 미실시 | AD33: 미실시 | AG33: 미실시
B34: =IF(OR(O34="-",O34="N/A"),"",COUNTA(O$5:O34)-(COUNTIF((O$5:O34),"-")+COUNTIF((O$5:O34),"N/A"))+COUNTIF((O$5:O34),"")) | C34: =IF($B34="","",CONCATENATE("TC-EIF-SCN-",$B34)) | D34: 8. Equipment Online Operation Scenario | O34: - | R34: - | U34: - | X34: - | AA34: - | AD34: - | AG34: -
B35: =B33+1 -> 22 | C35: =IF($B35="","",CONCATENATE("TC-EIF-SCN-",$B35)) -> TC-EIF-SCN-22 | D35: 8.1 Lot ID Report | E35: Lot ID를 Reading 시 보고 | F35: 1. Event Report Send | G35: S6F11 | H35: 20106 | I35: Optional | J35: Lv.1 | O35: N/A | R35: N/A | U35: N/A | X35: N/A | AA35: N/A | AD35: N/A | AG35: N/A
B36: =B35+1 -> 23 | C36: =IF($B36="","",CONCATENATE("TC-EIF-SCN-",$B36)) -> TC-EIF-SCN-23 | D36: 8.2 LOT ID Request | E36: Lot ID를 Request 시 보고 | F36: 1. Event Report Send | G36: S6F11 | H36: 20108 | I36: Optional | J36: Lv.1 | O36: N/A | R36: N/A | U36: N/A | X36: N/A | AA36: N/A | AD36: N/A | AG36: N/A
B37: =B36+1 -> 24 | C37: =IF($B37="","",CONCATENATE("TC-EIF-SCN-",$B37)) -> TC-EIF-SCN-24 | D37: 8.3 LOT_START | F37: 1. Enhanced Host Command Send | G37: S2F49 | I37: Optional | J37: Lv.1 | O37: N/A | R37: N/A | U37: N/A | X37: N/A | AA37: N/A | AD37: N/A | AG37: N/A
B38: =B37+1 -> 25 | C38: =IF($B38="","",CONCATENATE("TC-EIF-SCN-",$B38)) -> TC-EIF-SCN-25 | D38: 8.4 Lot Processing Started Report | E38: Lot Start 이벤트 보고 | F38: 1. Event Report Send | G38: S6F11 | H38: 20101 | I38: Optional | J38: Lv.1 | O38: N/A | R38: N/A | U38: N/A | X38: N/A | AA38: N/A | AD38: N/A | AG38: N/A
B39: =B38+1 -> 26 | C39: =IF($B39="","",CONCATENATE("TC-EIF-SCN-",$B39)) -> TC-EIF-SCN-26 | D39: 8.5 Product Data Request Report | E39: Product의 Product 정보 요청 시 보고 | F39: 1. Event Report Send | G39: S6F11 | H39: 20403 | I39: Optional | J39: Lv.1 | O39: N/A | R39: N/A | U39: N/A | X39: N/A | AA39: N/A | AD39: N/A | AG39: N/A
B40: =B39+1 -> 27 | C40: =IF($B40="","",CONCATENATE("TC-EIF-SCN-",$B40)) -> TC-EIF-SCN-27 | D40: 8.6 PRODUCT_DATA | F40: 1. Enhanced Host Command Send | G40: S2F49 | I40: Optional | J40: Lv.2 | O40: N/A | R40: N/A | U40: N/A | X40: N/A | AA40: N/A | AD40: N/A | AG40: N/A
B41: =B40+1 -> 28 | C41: =IF($B41="","",CONCATENATE("TC-EIF-SCN-",$B41)) -> TC-EIF-SCN-28 | D41: 8.7 Product Processing Completed Report | E41: Tray 내 Product 작업 완료 시 보고 | F41: 1. Enhanced Host Command Send | G41: S6F11 | H41: 20401 | I41: Optional | J41: Lv.2 | O41: N/A | R41: N/A | U41: N/A | X41: N/A | AA41: N/A | AD41: N/A | AG41: N/A
...

Sheet 03) Open Item
B1: ▣ Open Item (협의 필요 사항)
B3: NO | C3: 등록일자 | D3: 내용 및 처리 이력/결과 | E3: 해당 Test Case ID | F3: 상태 | G3: 완료예정일자 | H3: 완료일자 | I3: 담당부서 | J3: 비 고
